Workbook

Sheet Grafieken costwear
K2: Bruine Curduroy broek | L2: ='Prijslijst kleding'!E2 -> 0.1 | M2: ='Prijslijst kleding'!B2 -> 22.5
K3: ='Prijslijst kleding'!A3 -> Nette broek zwart | L3: ='Prijslijst kleding'!E3 -> 0 | M3: ='Prijslijst kleding'!B3 -> 0
K4: ='Prijslijst kleding'!A4 -> Dickies 874 zwart | L4: ='Prijslijst kleding'!E4 -> 0.29 | M4: ='Prijslijst kleding'!B4 -> 69
K5: ='Prijslijst kleding'!A5 -> Nette broek groen | L5: ='Prijslijst kleding'!E5 -> 0.43 | M5: ='Prijslijst kleding'!B5 -> 16
K6: ='Prijslijst kleding'!A6 -> Double pleaded beige linnen | L6: ='Prijslijst kleding'!E6 -> 10 | M6: ='Prijslijst kleding'!B6 -> 50
K7: ='Prijslijst kleding'!A7 -> Blauwe linnen broek | L7: ='Prijslijst kleding'!E7 -> 0.76 | M7: ='Prijslijst kleding'!B7 -> 49.9
K8: ='Prijslijst kleding'!A8 -> Spijkerbroek 20 euro | L8: ='Prijslijst kleding'!E8 -> 0.17 | M8: ='Prijslijst kleding'!B8 -> 20
K9: ='Prijslijst kleding'!A9 -> Spijkerbroek lichtblauw papa | L9: ='Prijslijst kleding'!E9 -> 0 | M9: ='Prijslijst kleding'!B9 -> 0
K10: Spijkerbroek levi's | L10: ='Prijslijst kleding'!E10 -> 0.17 | M10: ='Prijslijst kleding'!B10 -> 37.44
K11: ='Prijslijst kleding'!A11 -> Donkerblauwe spijkerbroek levi's | L11: ='Prijslijst kleding'!E11 -> 0.81 | M11: ='Prijslijst kleding'!B11 -> 34.04
K12: ='Prijslijst kleding'!A12 -> Beige levi's | L12: ='Prijslijst kleding'!E12 -> 0.21 | M12: ='Prijslijst kleding'!B12 -> 28.12
K13: ='Prijslijst kleding'!A14 -> Joggingbroek zwart/groene strepen | L13: ='Prijslijst kleding'!E14 -> 1.19 | M13: ='Prijslijst kleding'!B14 -> 50
K14: ='Prijslijst kleding'!A15 -> Pyjama' broek | L14: ='Prijslijst kleding'!E15 -> 0.25 | M14: ='Prijslijst kleding'!B15 -> 30
K15: ='Prijslijst kleding'!A16 -> Bruine korte broek | L15: ='Prijslijst kleding'!E16 -> 0.28 | M15: ='Prijslijst kleding'!B16 -> 20
K16: ='Prijslijst kleding'!A17 -> Beige korte broek | L16: ='Prijslijst kleding'!E17 -> 0.25 | M16: ='Prijslijst kleding'!B17 -> 20
K17: ='Prijslijst kleding'!A18 -> Blauwe pantalon pak | L17: ='Prijslijst kleding'!E18 -> 2.69 | M17: ='Prijslijst kleding'!B18 -> 161.25
K18: ='Prijslijst kleding'!A19 -> Blauwe korte broek | L18: ='Prijslijst kleding'!E19 -> 0.26 | M18: ='Prijslijst kleding'!B19 -> 5.95
K19: ='Prijslijst kleding'!A20 -> Decathlon Fitness short | L19: ='Prijslijst kleding'!E20 -> 0.36 | M19: ='Prijslijst kleding'!B20 -> 22.98
K20: ='Prijslijst kleding'!G2 -> Wit t-shirt | L20: ='Prijslijst kleding'!K2 -> 0.04 | M20: ='Prijslijst kleding'!H2 -> 30
K21: ='Prijslijst kleding'!G3 -> Wit t-shirt uniqlo | L21: ='Prijslijst kleding'!K3 -> 0.52 | M21: ='Prijslijst kleding'!H3 -> 139.5
K22: ='Prijslijst kleding'!G4 -> Wit Fila t-shirt | L22: ='Prijslijst kleding'!K4 -> 0.23 | M22: ='Prijslijst kleding'!H4 -> 20
K23: Wit Nike t-shirt | L23: ='Prijslijst kleding'!K5 -> 0.14 | M23: ='Prijslijst kleding'!H5 -> 30
K24: Wit Lost minds Athl. Track | L24: ='Prijslijst kleding'!K6 -> 0.24 | M24: ='Prijslijst kleding'!H6 -> 20
K25: Daily Aesthetikz t-shirt | L25: ='Prijslijst kleding'!K7 -> 0.77 | M25: ='Prijslijst kleding'!H7 -> 29.95
K26: ='Prijslijst kleding'!G8 -> The Good Life t-shirt | L26: ='Prijslijst kleding'!K8 -> 0.46 | M26: ='Prijslijst kleding'!H8 -> 19.95
K27: ='Prijslijst kleding'!G9 -> Mclaren t-shirt | L27: ='Prijslijst kleding'!K9 -> 0.61 | M27: ='Prijslijst kleding'!H9 -> 22.44
K28: ='Prijslijst kleding'!G10 -> Utah t-shirt | L28: ='Prijslijst kleding'!K10 -> 0.42 | M28: ='Prijslijst kleding'!H10 -> 11.76
K29: ='Prijslijst kleding'!G11 -> Bruin t-shirt | L29: ='Prijslijst kleding'!K11 -> 0.34 | M29: ='Prijslijst kleding'!H11 -> 15
K30: ='Prijslijst kleding'!G12 -> Bruin vis t-shirt | L30: ='Prijslijst kleding'!K12 -> 2.5 | M30: ='Prijslijst kleding'!H12 -> 24
K31: ='Prijslijst kleding'!G13 -> Groen t-shirt | L31: ='Prijslijst kleding'!K13 -> 0.71 | M31: ='Prijslijst kleding'!H13 -> 20
K32: ='Prijslijst kleding'!G14 -> Rood t-shirt | L32: ='Prijslijst kleding'!K14 -> 3.33 | M32: ='Prijslijst kleding'!H14 -> 20
K33: ='Prijslijst kleding'!G15 -> Grijs t-shirt | L33: ='Prijslijst kleding'!K15 -> 0.87 | M33: ='Prijslijst kleding'!H15 -> 20
K34: ='Prijslijst kleding'!M2 -> Groene trui knitted | L34: ='Prijslijst kleding'!Q2 -> 0.54 | M34: ='Prijslijst kleding'!N2 -> 38.5
K35: ='Prijslijst kleding'!M3 -> Witte trui knitted | L35: ='Prijslijst kleding'!Q3 -> 0.49 | M35: ='Prijslijst kleding'!N3 -> 40
K36: ='Prijslijst kleding'!M4 -> Coltrui wit | L36: ='Prijslijst kleding'!Q4 -> 3.5 | M36: ='Prijslijst kleding'!N4 -> 35
K37: ='Prijslijst kleding'!M5 -> Grijze trui, witte strepen | L37: ='Prijslijst kleding'!Q5 -> 1.33 | M37: ='Prijslijst kleding'!N5 -> 40
K38: ='Prijslijst kleding'!M6 -> Groene trui strepen | L38: ='Prijslijst kleding'!Q6 -> 0.63 | M38: ='Prijslijst kleding'!N6 -> 40
K39: ='Prijslijst kleding'!M7 -> Groene superdry trui | L39: ='Prijslijst kleding'!Q7 -> 0.79 | M39: ='Prijslijst kleding'!N7 -> 22
K40: ='Prijslijst kleding'!M8 -> Grijze trui | L40: ='Prijslijst kleding'!Q8 -> 7 | M40: ='Prijslijst kleding'!N8 -> 35
K41: ='Prijslijst kleding'!M9 -> Gele trui | L41: ='Prijslijst kleding'!Q9 -> 0.73 | M41: ='Prijslijst kleding'!N9 -> 40
...

Sheet Grafieken
A1: Broeken | N1: Algemeen
N2: Average number of wears per item per category
N3: Number of wears of colours
N4: Average spend per category
A40: Top 10 cheapest | E40: Top 10 most worn
A41: =IFERROR(__xludf.DUMMYFUNCTION("SMALL(FILTER(Data!$F$2:$F1000, Data!$D$2:$D1000=""broek"",Data!$F$2:$F1000>0), ROW(1:10) )"),0.1) -> 0.1 | B41: {=_xlfn.XLOOKUP(A41,Data!$F$2:$F1000,Data!$A$2:$A1000)} -> Bruine Curduroy broek | E41: =IFERROR(__xludf.DUMMYFUNCTION("LARGE(FILTER(Data!$E$2:$E1000,Data!$D$2:$D1000=""Broek""),ROW(1:10))"),242.0) -> 242 | F41: {=_xlfn.XLOOKUP(E41,Data!$E$2:$E1000,Data!$A$2:$A1000)} -> Dickies 874 zwart
A42: =IFERROR(__xludf.DUMMYFUNCTION("SMALL(FILTER(Data!$F$2:$F1000, Data!$D$2:$D1000=""broek"",Data!$F$2:$F1000>0), ROW(2:11) )"),0.17) -> 0.17 | B42: {=_xlfn.XLOOKUP(A42,Data!$F$2:$F1000,Data!$A$2:$A1000)} -> Spijkerbroek 20 euro | E42: =IFERROR(__xludf.DUMMYFUNCTION("LARGE(FILTER(Data!$E$2:$E1000,Data!$D$2:$D1000=""Broek""),ROW(2:11))"),225.0) -> 225 | F42: {=_xlfn.XLOOKUP(E42,Data!$E$2:$E1000,Data!$A$2:$A1000)} -> Bruine Curduroy broek
A43: =IFERROR(__xludf.DUMMYFUNCTION("SMALL(FILTER(Data!$F$2:$F1000, Data!$D$2:$D1000=""broek"",Data!$F$2:$F1000>0), ROW(3:12) )"),0.17) -> 0.17 | B43: {=_xlfn.XLOOKUP(A43,Data!$F$2:$F1000,Data!$A$2:$A1000)} -> Spijkerbroek 20 euro | E43: =IFERROR(__xludf.DUMMYFUNCTION("LARGE(FILTER(Data!$E$2:$E1000,Data!$D$2:$D1000=""Broek""),ROW(3:12))"),219.0) -> 219 | F43: {=_xlfn.XLOOKUP(E43,Data!$E$2:$E1000,Data!$A$2:$A1000)} -> Spijkerbroek levi's
A44: =IFERROR(__xludf.DUMMYFUNCTION("SMALL(FILTER(Data!$F$2:$F1000, Data!$D$2:$D1000=""broek"",Data!$F$2:$F1000>0), ROW(4:13) )"),0.21) -> 0.21 | B44: {=_xlfn.XLOOKUP(A44,Data!$F$2:$F1000,Data!$A$2:$A1000)} -> Beige levi's | E44: =IFERROR(__xludf.DUMMYFUNCTION("LARGE(FILTER(Data!$E$2:$E1000,Data!$D$2:$D1000=""Broek""),ROW(4:13))"),131.0) -> 131 | F44: {=_xlfn.XLOOKUP(E44,Data!$E$2:$E1000,Data!$A$2:$A1000)} -> Beige levi's
A45: =IFERROR(__xludf.DUMMYFUNCTION("SMALL(FILTER(Data!$F$2:$F1000, Data!$D$2:$D1000=""broek"",Data!$F$2:$F1000>0), ROW(5:14) )"),0.25) -> 0.25 | B45: {=_xlfn.XLOOKUP(A45,Data!$F$2:$F1000,Data!$A$2:$A1000)} -> Pyjama' broek | E45: =IFERROR(__xludf.DUMMYFUNCTION("LARGE(FILTER(Data!$E$2:$E1000,Data!$D$2:$D1000=""Broek""),ROW(5:14))"),122.0) -> 122 | F45: {=_xlfn.XLOOKUP(E45,Data!$E$2:$E1000,Data!$A$2:$A1000)} -> Pyjama' broek
A46: =IFERROR(__xludf.DUMMYFUNCTION("SMALL(FILTER(Data!$F$2:$F1000, Data!$D$2:$D1000=""broek"",Data!$F$2:$F1000>0), ROW(6:15) )"),0.25) -> 0.25 | B46: {=_xlfn.XLOOKUP(A46,Data!$F$2:$F1000,Data!$A$2:$A1000)} -> Pyjama' broek | E46: =IFERROR(__xludf.DUMMYFUNCTION("LARGE(FILTER(Data!$E$2:$E1000,Data!$D$2:$D1000=""Broek""),ROW(6:15))"),115.0) -> 115 | F46: {=_xlfn.XLOOKUP(E46,Data!$E$2:$E1000,Data!$A$2:$A1000)} -> Spijkerbroek 20 euro
A47: =IFERROR(__xludf.DUMMYFUNCTION("SMALL(FILTER(Data!$F$2:$F1000, Data!$D$2:$D1000=""broek"",Data!$F$2:$F1000>0), ROW(7:16) )"),0.26) -> 0.26 | B47: {=_xlfn.XLOOKUP(A47,Data!$F$2:$F1000,Data!$A$2:$A1000)} -> Lichtgroene trui | E47: =IFERROR(__xludf.DUMMYFUNCTION("LARGE(FILTER(Data!$E$2:$E1000,Data!$D$2:$D1000=""Broek""),ROW(7:16))"),79.0) -> 79 | F47: {=_xlfn.XLOOKUP(E47,Data!$E$2:$E1000,Data!$A$2:$A1000)} -> Beige korte broek
A48: =IFERROR(__xludf.DUMMYFUNCTION("SMALL(FILTER(Data!$F$2:$F1000, Data!$D$2:$D1000=""broek"",Data!$F$2:$F1000>0), ROW(8:17) )"),0.28) -> 0.28 | B48: {=_xlfn.XLOOKUP(A48,Data!$F$2:$F1000,Data!$A$2:$A1000)} -> Bruine korte broek | E48: =IFERROR(__xludf.DUMMYFUNCTION("LARGE(FILTER(Data!$E$2:$E1000,Data!$D$2:$D1000=""Broek""),ROW(8:17))"),71.0) -> 71 | F48: {=_xlfn.XLOOKUP(E48,Data!$E$2:$E1000,Data!$A$2:$A1000)} -> Bruine korte broek
A49: =IFERROR(__xludf.DUMMYFUNCTION("SMALL(FILTER(Data!$F$2:$F1000, Data!$D$2:$D1000=""broek"",Data!$F$2:$F1000>0), ROW(9:18) )"),0.29) -> 0.29 | B49: {=_xlfn.XLOOKUP(A49,Data!$F$2:$F1000,Data!$A$2:$A1000)} -> Dickies 874 zwart | E49: =IFERROR(__xludf.DUMMYFUNCTION("LARGE(FILTER(Data!$E$2:$E1000,Data!$D$2:$D1000=""Broek""),ROW(9:18))"),66.0) -> 66 | F49: {=_xlfn.XLOOKUP(E49,Data!$E$2:$E1000,Data!$A$2:$A1000)} -> Blauwe linnen broek
A50: =IFERROR(__xludf.DUMMYFUNCTION("SMALL(FILTER(Data!$F$2:$F1000, Data!$D$2:$D1000=""broek"",Data!$F$2:$F1000>0), ROW(10:19) )"),0.36) -> 0.36 | B50: {=_xlfn.XLOOKUP(A50,Data!$F$2:$F1000,Data!$A$2:$A1000)} -> Decathlon Fitness short | E50: =IFERROR(__xludf.DUMMYFUNCTION("LARGE(FILTER(Data!$E$2:$E1000,Data!$D$2:$D1000=""Broek""),ROW(10:19))"),63.0) -> 63 | F50: {=_xlfn.XLOOKUP(E50,Data!$E$2:$E1000,Data!$A$2:$A1000)} -> Groene trui strepen
A52: T-shirt
A54: Top 10 cheapest | E54: Top 10 most worn
A55: =IFERROR(__xludf.DUMMYFUNCTION("SMALL(FILTER(Data!$F$2:$F1000, Data!$D$2:$D1000=""T-shirt"",Data!$F$2:$F1000>0), ROW(1:10) )"),0.04) -> 0.04 | B55: {=_xlfn.XLOOKUP(A55,Data!$F$2:$F1000,Data!$A$2:$A1000)} -> Wit t-shirt | E55: =IFERROR(__xludf.DUMMYFUNCTION("LARGE(FILTER(Data!$E$2:$E1000,Data!$D$2:$D1000=""T-shirt""),ROW(1:10))"),741.0) -> 741 | F55: {=_xlfn.XLOOKUP(E55,Data!$E$2:$E1000,Data!$A$2:$A1000)} -> Wit t-shirt
A56: =IFERROR(__xludf.DUMMYFUNCTION("SMALL(FILTER(Data!$F$2:$F1000, Data!$D$2:$D1000=""T-shirt"",Data!$F$2:$F1000>0), ROW(2:11) )"),0.14) -> 0.14 | B56: {=_xlfn.XLOOKUP(A56,Data!$F$2:$F1000,Data!$A$2:$A1000)} -> Wit Nike t-shirt | E56: =IFERROR(__xludf.DUMMYFUNCTION("LARGE(FILTER(Data!$E$2:$E1000,Data!$D$2:$D1000=""T-shirt""),ROW(2:11))"),268.0) -> 268 | F56: {=_xlfn.XLOOKUP(E56,Data!$E$2:$E1000,Data!$A$2:$A1000)} -> Wit t-shirt uniqlo
A57: =IFERROR(__xludf.DUMMYFUNCTION("SMALL(FILTER(Data!$F$2:$F1000, Data!$D$2:$D1000=""T-shirt"",Data!$F$2:$F1000>0), ROW(3:12) )"),0.23) -> 0.23 | B57: {=_xlfn.XLOOKUP(A57,Data!$F$2:$F1000,Data!$A$2:$A1000)} -> Wit Fila t-shirt | E57: =IFERROR(__xludf.DUMMYFUNCTION("LARGE(FILTER(Data!$E$2:$E1000,Data!$D$2:$D1000=""T-shirt""),ROW(3:12))"),211.0) -> 211 | F57: {=_xlfn.XLOOKUP(E57,Data!$E$2:$E1000,Data!$A$2:$A1000)} -> Wit Nike t-shirt
A58: =IFERROR(__xludf.DUMMYFUNCTION("SMALL(FILTER(Data!$F$2:$F1000, Data!$D$2:$D1000=""T-shirt"",Data!$F$2:$F1000>0), ROW(4:13) )"),0.24) -> 0.24 | B58: {=_xlfn.XLOOKUP(A58,Data!$F$2:$F1000,Data!$A$2:$A1000)} -> Wit Lost minds Athl. Track | E58: =IFERROR(__xludf.DUMMYFUNCTION("LARGE(FILTER(Data!$E$2:$E1000,Data!$D$2:$D1000=""T-shirt""),ROW(4:13))"),86.0) -> 86 | F58: {=_xlfn.XLOOKUP(E58,Data!$E$2:$E1000,Data!$A$2:$A1000)} -> Wit Fila t-shirt
A59: =IFERROR(__xludf.DUMMYFUNCTION("SMALL(FILTER(Data!$F$2:$F1000, Data!$D$2:$D1000=""T-shirt"",Data!$F$2:$F1000>0), ROW(5:14) )"),0.34) -> 0.34 | B59: {=_xlfn.XLOOKUP(A59,Data!$F$2:$F1000,Data!$A$2:$A1000)} -> Bruin t-shirt | E59: =IFERROR(__xludf.DUMMYFUNCTION("LARGE(FILTER(Data!$E$2:$E1000,Data!$D$2:$D1000=""T-shirt""),ROW(5:14))"),82.0) -> 82 | F59: {=_xlfn.XLOOKUP(E59,Data!$E$2:$E1000,Data!$A$2:$A1000)} -> Wit Lost minds Athl. Track
A60: =IFERROR(__xludf.DUMMYFUNCTION("SMALL(FILTER(Data!$F$2:$F1000, Data!$D$2:$D1000=""T-shirt"",Data!$F$2:$F1000>0), ROW(6:15) )"),0.42) -> 0.42 | B60: {=_xlfn.XLOOKUP(A60,Data!$F$2:$F1000,Data!$A$2:$A1000)} -> Utah t-shirt | E60: =IFERROR(__xludf.DUMMYFUNCTION("LARGE(FILTER(Data!$E$2:$E1000,Data!$D$2:$D1000=""T-shirt""),ROW(6:15))"),44.0) -> 44 | F60: {=_xlfn.XLOOKUP(E60,Data!$E$2:$E1000,Data!$A$2:$A1000)} -> Bruin t-shirt
A61: =IFERROR(__xludf.DUMMYFUNCTION("SMALL(FILTER(Data!$F$2:$F1000, Data!$D$2:$D1000=""T-shirt"",Data!$F$2:$F1000>0), ROW(7:16) )"),0.45) -> 0.45 | B61: {=_xlfn.XLOOKUP(A61,Data!$F$2:$F1000,Data!$A$2:$A1000)} -> Flowfrog t-shirt | E61: =IFERROR(__xludf.DUMMYFUNCTION("LARGE(FILTER(Data!$E$2:$E1000,Data!$D$2:$D1000=""T-shirt""),ROW(7:16))"),43.0) -> 43 | F61: {=_xlfn.XLOOKUP(E61,Data!$E$2:$E1000,Data!$A$2:$A1000)} -> The Good Life t-shirt
A62: =IFERROR(__xludf.DUMMYFUNCTION("SMALL(FILTER(Data!$F$2:$F1000, Data!$D$2:$D1000=""T-shirt"",Data!$F$2:$F1000>0), ROW(8:17) )"),0.46) -> 0.46 | B62: {=_xlfn.XLOOKUP(A62,Data!$F$2:$F1000,Data!$A$2:$A1000)} -> The Good Life t-shirt | E62: =IFERROR(__xludf.DUMMYFUNCTION("LARGE(FILTER(Data!$E$2:$E1000,Data!$D$2:$D1000=""T-shirt""),ROW(8:17))"),39.0) -> 39 | F62: {=_xlfn.XLOOKUP(E62,Data!$E$2:$E1000,Data!$A$2:$A1000)} -> Daily Aesthetikz t-shirt
A63: =IFERROR(__xludf.DUMMYFUNCTION("SMALL(FILTER(Data!$F$2:$F1000, Data!$D$2:$D1000=""T-shirt"",Data!$F$2:$F1000>0), ROW(9:18) )"),0.52) -> 0.52 | B63: {=_xlfn.XLOOKUP(A63,Data!$F$2:$F1000,Data!$A$2:$A1000)} -> Wit t-shirt uniqlo | E63: =IFERROR(__xludf.DUMMYFUNCTION("LARGE(FILTER(Data!$E$2:$E1000,Data!$D$2:$D1000=""T-shirt""),ROW(9:18))"),37.0) -> 37 | F63: {=_xlfn.XLOOKUP(E63,Data!$E$2:$E1000,Data!$A$2:$A1000)} -> Nette broek groen
A64: =IFERROR(__xludf.DUMMYFUNCTION("SMALL(FILTER(Data!$F$2:$F1000, Data!$D$2:$D1000=""T-shirt"",Data!$F$2:$F1000>0), ROW(10:19) )"),0.53) -> 0.53 | B64: {=_xlfn.XLOOKUP(A64,Data!$F$2:$F1000,Data!$A$2:$A1000)} -> Bruine fleece trui | E64: =IFERROR(__xludf.DUMMYFUNCTION("LARGE(FILTER(Data!$E$2:$E1000,Data!$D$2:$D1000=""T-shirt""),ROW(10:19))"),29.0) -> 29 | F64: {=_xlfn.XLOOKUP(E64,Data!$E$2:$E1000,Data!$A$2:$A1000)} -> Rode fleece trui
A66: Trui
A68: Top 10 cheapest | E68: Top 10 most worn
A69: =IFERROR(__xludf.DUMMYFUNCTION("SMALL(FILTER(Data!$F$2:$F1000, Data!$D$2:$D1000=""Trui"",Data!$F$2:$F1000>0), ROW(1:10) )"),0.15) -> 0.15 | B69: {=_xlfn.XLOOKUP(A69,Data!$F$2:$F1000,Data!$A$2:$A1000)} -> Rode Sweater | E69: =IFERROR(__xludf.DUMMYFUNCTION("LARGE(FILTER(Data!$E$2:$E1000,Data!$D$2:$D1000=""Trui""),ROW(1:10))"),105.0) -> 105 | F69: {=_xlfn.XLOOKUP(E69,Data!$E$2:$E1000,Data!$A$2:$A1000)} -> Blauw/zwart/wit geblokt jasje
A70: =IFERROR(__xludf.DUMMYFUNCTION("SMALL(FILTER(Data!$F$2:$F1000, Data!$D$2:$D1000=""Trui"",Data!$F$2:$F1000>0), ROW(2:11) )"),0.24) -> 0.24 | B70: {=_xlfn.XLOOKUP(A70,Data!$F$2:$F1000,Data!$A$2:$A1000)} -> Wit Lost minds Athl. Track | E70: =IFERROR(__xludf.DUMMYFUNCTION("LARGE(FILTER(Data!$E$2:$E1000,Data!$D$2:$D1000=""Trui""),ROW(2:11))"),97.0) -> 97 | F70: {=_xlfn.XLOOKUP(E70,Data!$E$2:$E1000,Data!$A$2:$A1000)} -> Rode Sweater
A71: =IFERROR(__xludf.DUMMYFUNCTION("SMALL(FILTER(Data!$F$2:$F1000, Data!$D$2:$D1000=""Trui"",Data!$F$2:$F1000>0), ROW(3:12) )"),0.26) -> 0.26 | B71: {=_xlfn.XLOOKUP(A71,Data!$F$2:$F1000,Data!$A$2:$A1000)} -> Lichtgroene trui | E71: =IFERROR(__xludf.DUMMYFUNCTION("LARGE(FILTER(Data!$E$2:$E1000,Data!$D$2:$D1000=""Trui""),ROW(3:12))"),96.0) -> 96 | F71: {=_xlfn.XLOOKUP(E71,Data!$E$2:$E1000,Data!$A$2:$A1000)} -> Ralph Lauren Sweater
A72: =IFERROR(__xludf.DUMMYFUNCTION("SMALL(FILTER(Data!$F$2:$F1000, Data!$D$2:$D1000=""Trui"",Data!$F$2:$F1000>0), ROW(4:13) )"),0.31) -> 0.31 | B72: {=_xlfn.XLOOKUP(A72,Data!$F$2:$F1000,Data!$A$2:$A1000)} -> Bruine trui | E72: =IFERROR(__xludf.DUMMYFUNCTION("LARGE(FILTER(Data!$E$2:$E1000,Data!$D$2:$D1000=""Trui""),ROW(4:13))"),82.0) -> 82 | F72: {=_xlfn.XLOOKUP(E72,Data!$E$2:$E1000,Data!$A$2:$A1000)} -> Wit Lost minds Athl. Track
A73: =IFERROR(__xludf.DUMMYFUNCTION("SMALL(FILTER(Data!$F$2:$F1000, Data!$D$2:$D1000=""Trui"",Data!$F$2:$F1000>0), ROW(5:14) )"),0.34) -> 0.34 | B73: {=_xlfn.XLOOKUP(A73,Data!$F$2:$F1000,Data!$A$2:$A1000)} -> Bruin t-shirt | E73: =IFERROR(__xludf.DUMMYFUNCTION("LARGE(FILTER(Data!$E$2:$E1000,Data!$D$2:$D1000=""Trui""),ROW(5:14))"),78.0) -> 78 | F73: {=_xlfn.XLOOKUP(E73,Data!$E$2:$E1000,Data!$A$2:$A1000)} -> Lichtgroene trui
A74: =IFERROR(__xludf.DUMMYFUNCTION("SMALL(FILTER(Data!$F$2:$F1000, Data!$D$2:$D1000=""Trui"",Data!$F$2:$F1000>0), ROW(6:15) )"),0.35) -> 0.35 | B74: {=_xlfn.XLOOKUP(A74,Data!$F$2:$F1000,Data!$A$2:$A1000)} -> Blauwe lange mouwen polo | E74: =IFERROR(__xludf.DUMMYFUNCTION("LARGE(FILTER(Data!$E$2:$E1000,Data!$D$2:$D1000=""Trui""),ROW(6:15))"),71.0) -> 71 | F74: {=_xlfn.XLOOKUP(E74,Data!$E$2:$E1000,Data!$A$2:$A1000)} -> Bruine korte broek
A75: =IFERROR(__xludf.DUMMYFUNCTION("SMALL(FILTER(Data!$F$2:$F1000, Data!$D$2:$D1000=""Trui"",Data!$F$2:$F1000>0), ROW(7:16) )"),0.43) -> 0.43 | B75: {=_xlfn.XLOOKUP(A75,Data!$F$2:$F1000,Data!$A$2:$A1000)} -> Nette broek groen | E75: =IFERROR(__xludf.DUMMYFUNCTION("LARGE(FILTER(Data!$E$2:$E1000,Data!$D$2:$D1000=""Trui""),ROW(7:16))"),66.0) -> 66 | F75: {=_xlfn.XLOOKUP(E75,Data!$E$2:$E1000,Data!$A$2:$A1000)} -> Blauwe linnen broek
A76: =IFERROR(__xludf.DUMMYFUNCTION("SMALL(FILTER(Data!$F$2:$F1000, Data!$D$2:$D1000=""Trui"",Data!$F$2:$F1000>0), ROW(8:17) )"),0.49) -> 0.49 | B76: {=_xlfn.XLOOKUP(A76,Data!$F$2:$F1000,Data!$A$2:$A1000)} -> Witte trui knitted | E76: =IFERROR(__xludf.DUMMYFUNCTION("LARGE(FILTER(Data!$E$2:$E1000,Data!$D$2:$D1000=""Trui""),ROW(8:17))"),63.0) -> 63 | F76: {=_xlfn.XLOOKUP(E76,Data!$E$2:$E1000,Data!$A$2:$A1000)} -> Groene trui strepen
A77: =IFERROR(__xludf.DUMMYFUNCTION("SMALL(FILTER(Data!$F$2:$F1000, Data!$D$2:$D1000=""Trui"",Data!$F$2:$F1000>0), ROW(9:18) )"),0.53) -> 0.53 | B77: {=_xlfn.XLOOKUP(A77,Data!$F$2:$F1000,Data!$A$2:$A1000)} -> Bruine fleece trui | E77: =IFERROR(__xludf.DUMMYFUNCTION("LARGE(FILTER(Data!$E$2:$E1000,Data!$D$2:$D1000=""Trui""),ROW(9:18))"),59.0) -> 59 | F77: {=_xlfn.XLOOKUP(E77,Data!$E$2:$E1000,Data!$A$2:$A1000)} -> Blauwe lange mouwen polo
A78: =IFERROR(__xludf.DUMMYFUNCTION("SMALL(FILTER(Data!$F$2:$F1000, Data!$D$2:$D1000=""Trui"",Data!$F$2:$F1000>0), ROW(10:19) )"),0.54) -> 0.54 | B78: {=_xlfn.XLOOKUP(A78,Data!$F$2:$F1000,Data!$A$2:$A1000)} -> Groene trui knitted | E78: =IFERROR(__xludf.DUMMYFUNCTION("LARGE(FILTER(Data!$E$2:$E1000,Data!$D$2:$D1000=""Trui""),ROW(10:19))"),58.0) -> 58 | F78: {=_xlfn.XLOOKUP(E78,Data!$E$2:$E1000,Data!$A$2:$A1000)} -> Beige trui

Sheet Median cpw
A1: ='Prijs verandering'!C1 -> January 2024 | B1: ='Prijs verandering'!D1 -> February 2024 | C1: ='Prijs verandering'!E1 -> March 2024 | D1: ='Prijs verandering'!F1 -> April 2024 | E1: ='Prijs verandering'!G1 -> May 2024 | F1: ='Prijs verandering'!H1 -> June 2024 | G1: ='Prijs verandering'!I1 -> July 2024 | H1: ='Prijs verandering'!J1 -> August 2024 | ... AF1: ='Prijs verandering'!AH1
A2: =ROUND(MEDIAN('Prijs verandering'!C2:C1000),2) -> 0.91 | B2: =ROUND(MEDIAN('Prijs verandering'!D2:D1000),2) -> 0.91 | C2: =ROUND(MEDIAN('Prijs verandering'!E2:E1000),2) -> 0.91 | D2: =ROUND(MEDIAN('Prijs verandering'!F2:F1000),2) -> 0.91 | E2: =ROUND(MEDIAN('Prijs verandering'!G2:G1000),2) -> 0.81 | F2: =ROUND(MEDIAN('Prijs verandering'!H2:H1000),2) -> 0.8 | G2: =ROUND(MEDIAN('Prijs verandering'!I2:I1000),2) -> 0.82 | H2: =ROUND(MEDIAN('Prijs verandering'!J2:J1000),2) -> 0.78 | ... AA2: =ROUND(MEDIAN('Prijs verandering'!AC2:AC1000),2) -> 0.86

Sheet Prijs verandering
A1: Naam | B1: Cost per wear | C1: January 2024 | D1: February 2024 | E1: March 2024 | F1: April 2024 | G1: May 2024 | H1: June 2024 | I1: July 2024 | J1: August 2024 | K1: September 2024 | L1: October 2024 | M1: November 2024 | N1: December 2024 | O1: January 2025 | P1: February 2025 | Q1: March 2025 | R1: April 2025 | S1: May 2025 | T1: June 2025 | U1: July 2025 | V1: August 2025 | W1: September 2025 | X1: October 2025 | Y1: November 2025 | Z1: December 2025 | AA1: January 2026 | AB1: February 2026 | AC1: March 2026
A2: =IFERROR(__xludf.DUMMYFUNCTION("FILTER(Data!A2:A1000, Data!A2:A1000 <> """")"),"Bruine Curduroy broek") -> Bruine Curduroy broek | B2: =Data!F2:F1000 -> 0.1 | C2: =IFERROR(ROUND(Data!B2/(SUMPRODUCT(('Form responses 1'!$B$2:$B1000 = A2) * ('Form responses 1'!$A$2:$A1000 <= DATE(2024, 1, 31))) + SUMPRODUCT(('Form responses 1'!$C$2:$C1000 = A2) * ('Form responses 1'!$A$2:$A1000 <= DATE(2024, 1, 31))) + SUMPRODUCT(('Form responses 1'!$D$2:$D1000 = A2) * ('Form responses 1'!$A$2:$A1000 <= DATE(2024, 1, 31))) + SUMPRODUCT(('Form responses 1'!$E$2:$E1000 = A2) * ('Form responses 1'!$A$2:$A1000 <= DATE(2024, 1, 31))) + SUMPRODUCT(('Form responses 1'!$F$2:$F1000 = A2) * ('Form responses 1'!$A$2:$A1000 <= DATE(2024, 1, 31))) + SUMPRODUCT(('Form responses 1'!$G$2:$G1000 = A2) * ('Form responses 1'!$A$2:$A1000 <= DATE(2024, 1, 31)))), 2), "-") -> 0.16 | D2: =IFERROR(ROUND(Data!B2/(SUMPRODUCT(('Form responses 1'!$B$2:$B1000 = A2) * ('Form responses 1'!$A$2:$A1000 <= DATE(2024, 2, 29))) + SUMPRODUCT(('Form responses 1'!$C$2:$C1000 = A2) * ('Form responses 1'!$A$2:$A1000 <= DATE(2024, 2, 29))) + SUMPRODUCT(('Form responses 1'!$D$2:$D1000 = A2) * ('Form responses 1'!$A$2:$A1000 <= DATE(2024, 2, 29))) + SUMPRODUCT(('Form responses 1'!$E$2:$E1000 = A2) * ('Form responses 1'!$A$2:$A1000 <= DATE(2024, 2, 29))) + SUMPRODUCT(('Form responses 1'!$F$2:$F1000 = A2) * ('Form responses 1'!$A$2:$A1000 <= DATE(2024, 2, 29))) + SUMPRODUCT(('Form responses 1'!$G$2:$G1000 = A2) * ('Form responses 1'!$A$2:$A1000 <= DATE(2024, 2, 29)))), 2), "-") -> 0.16 | E2: =IFERROR(ROUND(Data!B2/(SUMPRODUCT(('Form responses 1'!$B$2:$B1000 = A2) * ('Form responses 1'!$A$2:$A1000 <= DATE(2024, 3, 31))) + SUMPRODUCT(('Form responses 1'!$C$2:$C1000 = A2) * ('Form responses 1'!$A$2:$A1000 <= DATE(2024, 3, 31))) + SUMPRODUCT(('Form responses 1'!$D$2:$D1000 = A2) * ('Form responses 1'!$A$2:$A1000 <= DATE(2024, 3, 31))) + SUMPRODUCT(('Form responses 1'!$E$2:$E1000 = A2) * ('Form responses 1'!$A$2:$A1000 <= DATE(2024, 3, 31))) + SUMPRODUCT(('Form responses 1'!$F$2:$F1000 = A2) * ('Form responses 1'!$A$2:$A1000 <= DATE(2024, 3, 31))) + SUMPRODUCT(('Form responses 1'!$G$2:$G1000 = A2) * ('Form responses 1'!$A$2:$A1000 <= DATE(2024, 3, 31)))), 2), "-") -> 0.16 | F2: =IFERROR(ROUND(Data!B2/(SUMPRODUCT(('Form responses 1'!$B$2:$B1000 = A2) * ('Form responses 1'!$A$2:$A1000 <= DATE(2024, 4, 30))) + SUMPRODUCT(('Form responses 1'!$C$2:$C1000 = A2) * ('Form responses 1'!$A$2:$A1000 <= DATE(2024, 4, 30))) + SUMPRODUCT(('Form responses 1'!$D$2:$D1000 = A2) * ('Form responses 1'!$A$2:$A1000 <= DATE(2024, 4, 30))) + SUMPRODUCT(('Form responses 1'!$E$2:$E1000 = A2) * ('Form responses 1'!$A$2:$A1000 <= DATE(2024, 4, 30))) + SUMPRODUCT(('Form responses 1'!$F$2:$F1000 = A2) * ('Form responses 1'!$A$2:$A1000 <= DATE(2024, 4, 30))) + SUMPRODUCT(('Form responses 1'!$G$2:$G1000 = A2) * ('Form responses 1'!$A$2:$A1000 <= DATE(2024, 4, 30)))), 2), "-") -> 0.16 | G2: =IFERROR(ROUND(Data!B2/(SUMPRODUCT(('Form responses 1'!$B$2:$B1000 = A2) * ('Form responses 1'!$A$2:$A1000 <= DATE(2024, 5, 31))) + SUMPRODUCT(('Form responses 1'!$C$2:$C1000 = A2) * ('Form responses 1'!$A$2:$A1000 <= DATE(2024, 5, 31))) + SUMPRODUCT(('Form responses 1'!$D$2:$D1000 = A2) * ('Form responses 1'!$A$2:$A1000 <= DATE(2024, 5, 31))) + SUMPRODUCT(('Form responses 1'!$E$2:$E1000 = A2) * ('Form responses 1'!$A$2:$A1000 <= DATE(2024, 5, 31))) + SUMPRODUCT(('Form responses 1'!$F$2:$F1000 = A2) * ('Form responses 1'!$A$2:$A1000 <= DATE(2024, 5, 31))) + SUMPRODUCT(('Form responses 1'!$G$2:$G1000 = A2) * ('Form responses 1'!$A$2:$A1000 <= DATE(2024, 5, 31)))), 2), "-") -> 0.15 | H2: =IFERROR(ROUND(Data!B2/(SUMPRODUCT(('Form responses 1'!$B$2:$B1000 = A2) * ('Form responses 1'!$A$2:$A1000 <= DATE(2024, 6, 30))) + SUMPRODUCT(('Form responses 1'!$C$2:$C1000 = A2) * ('Form responses 1'!$A$2:$A1000 <= DATE(2024, 6, 30))) + SUMPRODUCT(('Form responses 1'!$D$2:$D1000 = A2) * ('Form responses 1'!$A$2:$A1000 <= DATE(2024, 6, 30))) + SUMPRODUCT(('Form responses 1'!$E$2:$E1000 = A2) * ('Form responses 1'!$A$2:$A1000 <= DATE(2024, 6, 30))) + SUMPRODUCT(('Form responses 1'!$F$2:$F1000 = A2) * ('Form responses 1'!$A$2:$A1000 <= DATE(2024, 6, 30))) + SUMPRODUCT(('Form responses 1'!$G$2:$G1000 = A2) * ('Form responses 1'!$A$2:$A1000 <= DATE(2024, 6, 30)))), 2), "-") -> 0.15 | I2: =IFERROR(ROUND(Data!B2/(SUMPRODUCT(('Form responses 1'!$B$2:$B1000 = A2) * ('Form responses 1'!$A$2:$A1000 <= DATE(2024, 7, 31))) + SUMPRODUCT(('Form responses 1'!$C$2:$C1000 = A2) * ('Form responses 1'!$A$2:$A1000 <= DATE(2024, 7, 31))) + SUMPRODUCT(('Form responses 1'!$D$2:$D1000 = A2) * ('Form responses 1'!$A$2:$A1000 <= DATE(2024, 7, 31))) + SUMPRODUCT(('Form responses 1'!$E$2:$E1000 = A2) * ('Form responses 1'!$A$2:$A1000 <= DATE(2024, 7, 31))) + SUMPRODUCT(('Form responses 1'!$F$2:$F1000 = A2) * ('Form responses 1'!$A$2:$A1000 <= DATE(2024, 7, 31))) + SUMPRODUCT(('Form responses 1'!$G$2:$G1000 = A2) * ('Form responses 1'!$A$2:$A1000 <= DATE(2024, 7, 31)))), 2), "-") -> 0.15 | J2: =IFERROR(ROUND(Data!B2/(SUMPRODUCT(('Form responses 1'!$B$2:$B1000 = A2) * ('Form responses 1'!$A$2:$A1000 <= DATE(2024, 8, 31))) + SUMPRODUCT(('Form responses 1'!$C$2:$C1000 = A2) * ('Form responses 1'!$A$2:$A1000 <= DATE(2024, 8, 31))) + SUMPRODUCT(('Form responses 1'!$D$2:$D1000 = A2) * ('Form responses 1'!$A$2:$A1000 <= DATE(2024, 8, 31))) + SUMPRODUCT(('Form responses 1'!$E$2:$E1000 = A2) * ('Form responses 1'!$A$2:$A1000 <= DATE(2024, 8, 31))) + SUMPRODUCT(('Form responses 1'!$F$2:$F1000 = A2) * ('Form responses 1'!$A$2:$A1000 <= DATE(2024, 8, 31))) + SUMPRODUCT(('Form responses 1'!$G$2:$G1000 = A2) * ('Form responses 1'!$A$2:$A1000 <= DATE(2024, 8, 31)))), 2), "-") -> 0.15 | K2: =IFERROR(ROUND(Data!B2/(SUMPRODUCT(('Form responses 1'!$B$2:$B1000 = A2) * ('Form responses 1'!$A$2:$A1000 <= DATE(2024, 9, 30))) + SUMPRODUCT(('Form responses 1'!$C$2:$C1000 = A2) * ('Form responses 1'!$A$2:$A1000 <= DATE(2024, 9, 30))) + SUMPRODUCT(('Form responses 1'!$D$2:$D1000 = A2) * ('Form responses 1'!$A$2:$A1000 <= DATE(2024, 9, 30))) + SUMPRODUCT(('Form responses 1'!$E$2:$E1000 = A2) * ('Form responses 1'!$A$2:$A1000 <= DATE(2024, 9, 30))) + SUMPRODUCT(('Form responses 1'!$F$2:$F1000 = A2) * ('Form responses 1'!$A$2:$A1000 <= DATE(2024, 9, 30))) + SUMPRODUCT(('Form responses 1'!$G$2:$G1000 = A2) * ('Form responses 1'!$A$2:$A1000 <= DATE(2024, 9, 30)))), 2), "-") -> 0.14 | L2: =IFERROR(ROUND(Data!B2/(SUMPRODUCT(('Form responses 1'!$B$2:$B1000 = A2) * ('Form responses 1'!$A$2:$A1000 <= DATE(2024, 10, 31))) + SUMPRODUCT(('Form responses 1'!$C$2:$C1000 = A2) * ('Form responses 1'!$A$2:$A1000 <= DATE(2024, 10, 31))) + SUMPRODUCT(('Form responses 1'!$D$2:$D1000 = A2) * ('Form responses 1'!$A$2:$A1000 <= DATE(2024, 10, 31))) + SUMPRODUCT(('Form responses 1'!$E$2:$E1000 = A2) * ('Form responses 1'!$A$2:$A1000 <= DATE(2024, 10, 31))) + SUMPRODUCT(('Form responses 1'!$F$2:$F1000 = A2) * ('Form responses 1'!$A$2:$A1000 <= DATE(2024, 10, 31))) + SUMPRODUCT(('Form responses 1'!$G$2:$G1000 = A2) * ('Form responses 1'!$A$2:$A1000 <= DATE(2024, 10, 31)))), 2), "-") -> 0.13 | M2: =IFERROR(ROUND(Data!B2/(SUMPRODUCT(('Form responses 1'!$B$2:$B1000 = A2) * ('Form responses 1'!$A$2:$A1000 <= DATE(2024, 11, 30))) + SUMPRODUCT(('Form responses 1'!$C$2:$C1000 = A2) * ('Form responses 1'!$A$2:$A1000 <= DATE(2024, 11, 30))) + SUMPRODUCT(('Form responses 1'!$D$2:$D1000 = A2) * ('Form responses 1'!$A$2:$A1000 <= DATE(2024, 11, 30))) + SUMPRODUCT(('Form responses 1'!$E$2:$E1000 = A2) * ('Form responses 1'!$A$2:$A1000 <= DATE(2024, 11, 30))) + SUMPRODUCT(('Form responses 1'!$F$2:$F1000 = A2) * ('Form responses 1'!$A$2:$A1000 <= DATE(2024, 11, 30))) + SUMPRODUCT(('Form responses 1'!$G$2:$G1000 = A2) * ('Form responses 1'!$A$2:$A1000 <= DATE(2024, 11, 30)))), 2), "-") -> 0.13 | N2: =IFERROR(ROUND(Data!B2/(SUMPRODUCT(('Form responses 1'!$B$2:$B1000 = A2) * ('Form responses 1'!$A$2:$A1000 <= DATE(2024, 12, 31))) + SUMPRODUCT(('Form responses 1'!$C$2:$C1000 = A2) * ('Form responses 1'!$A$2:$A1000 <= DATE(2024, 12, 31))) + SUMPRODUCT(('Form responses 1'!$D$2:$D1000 = A2) * ('Form responses 1'!$A$2:$A1000 <= DATE(2024, 12, 31))) + SUMPRODUCT(('Form responses 1'!$E$2:$E1000 = A2) * ('Form responses 1'!$A$2:$A1000 <= DATE(2024, 12, 31))) + SUMPRODUCT(('Form responses 1'!$F$2:$F1000 = A2) * ('Form responses 1'!$A$2:$A1000 <= DATE(2024, 12, 31))) + SUMPRODUCT(('Form responses 1'!$G$2:$G1000 = A2) * ('Form responses 1'!$A$2:$A1000 <= DATE(2024, 12, 31)))), 2), "-") -> 0.12 | O2: =IFERROR(ROUND(Data!B2/(SUMPRODUCT(('Form responses 1'!$B$2:$B1000 = A2) * ('Form responses 1'!$A$2:$A1000 <= DATE(2025, 1, 31))) + SUMPRODUCT(('Form responses 1'!$C$2:$C1000 = A2) * ('Form responses 1'!$A$2:$A1000 <= DATE(2025, 1, 31))) + SUMPRODUCT(('Form responses 1'!$D$2:$D1000 = A2) * ('Form responses 1'!$A$2:$A1000 <= DATE(2025, 1, 31))) + SUMPRODUCT(('Form responses 1'!$E$2:$E1000 = A2) * ('Form responses 1'!$A$2:$A1000 <= DATE(2025, 1, 31))) + SUMPRODUCT(('Form responses 1'!$F$2:$F1000 = A2) * ('Form responses 1'!$A$2:$A1000 <= DATE(2025, 1, 31))) + SUMPRODUCT(('Form responses 1'!$G$2:$G1000 = A2) * ('Form responses 1'!$A$2:$A1000 <= DATE(2025, 1, 31)))), 2), "-") -> 0.12 | P2: =IFERROR(ROUND(Data!B2/(SUMPRODUCT(('Form responses 1'!$B$2:$B1000 = A2) * ('Form responses 1'!$A$2:$A1000 <= DATE(2025, 2, 28))) + SUMPRODUCT(('Form responses 1'!$C$2:$C1000 = A2) * ('Form responses 1'!$A$2:$A1000 <= DATE(2025, 2, 28))) + SUMPRODUCT(('Form responses 1'!$D$2:$D1000 = A2) * ('Form responses 1'!$A$2:$A1000 <= DATE(2025, 2, 28))) + SUMPRODUCT(('Form responses 1'!$E$2:$E1000 = A2) * ('Form responses 1'!$A$2:$A1000 <= DATE(2025, 2, 28))) + SUMPRODUCT(('Form responses 1'!$F$2:$F1000 = A2) * ('Form responses 1'!$A$2:$A1000 <= DATE(2025, 2, 28))) + SUMPRODUCT(('Form responses 1'!$G$2:$G1000 = A2) * ('Form responses 1'!$A$2:$A1000 <= DATE(2025, 2, 28)))), 2), "-") -> 0.12 | Q2: =IFERROR(ROUND(Data!B2/(SUMPRODUCT(('Form responses 1'!$B$2:$B1000 = A2) * ('Form responses 1'!$A$2:$A1000 <= DATE(2025, 3, 31))) + SUMPRODUCT(('Form responses 1'!$C$2:$C1000 = A2) * ('Form responses 1'!$A$2:$A1000 <= DATE(2025, 3, 31))) + SUMPRODUCT(('Form responses 1'!$D$2:$D1000 = A2) * ('Form responses 1'!$A$2:$A1000 <= DATE(2025, 3, 31))) + SUMPRODUCT(('Form responses 1'!$E$2:$E1000 = A2) * ('Form responses 1'!$A$2:$A1000 <= DATE(2025, 3, 31))) + SUMPRODUCT(('Form responses 1'!$F$2:$F1000 = A2) * ('Form responses 1'!$A$2:$A1000 <= DATE(2025, 3, 31))) + SUMPRODUCT(('Form responses 1'!$G$2:$G1000 = A2) * ('Form responses 1'!$A$2:$A1000 <= DATE(2025, 3, 31)))),2),"-") -> 0.12 | R2: =IFERROR(ROUND(Data!B2/(SUMPRODUCT(('Form responses 1'!$B$2:$B1000 = A2) * ('Form responses 1'!$A$2:$A1000 <= DATE(2025, 4, 30))) + SUMPRODUCT(('Form responses 1'!$C$2:$C1000 = A2) * ('Form responses 1'!$A$2:$A1000 <= DATE(2025, 4, 30))) + SUMPRODUCT(('Form responses 1'!$D$2:$D1000 = A2) * ('Form responses 1'!$A$2:$A1000 <= DATE(2025, 4, 30))) + SUMPRODUCT(('Form responses 1'!$E$2:$E1000 = A2) * ('Form responses 1'!$A$2:$A1000 <= DATE(2025, 4, 30))) + SUMPRODUCT(('Form responses 1'!$F$2:$F1000 = A2) * ('Form responses 1'!$A$2:$A1000 <= DATE(2025, 4, 30))) + SUMPRODUCT(('Form responses 1'!$G$2:$G1000 = A2) * ('Form responses 1'!$A$2:$A1000 <= DATE(2025, 4, 30)))), 2), "-") -> 0.11 | S2: =IFERROR(ROUND(Data!B2/(SUMPRODUCT(('Form responses 1'!$B$2:$B1000 = A2) * ('Form responses 1'!$A$2:$A1000 <= DATE(2025, 5, 31))) + SUMPRODUCT(('Form responses 1'!$C$2:$C1000 = A2) * ('Form responses 1'!$A$2:$A1000 <= DATE(2025, 5, 31))) + SUMPRODUCT(('Form responses 1'!$D$2:$D1000 = A2) * ('Form responses 1'!$A$2:$A1000 <= DATE(2025, 5, 31))) + SUMPRODUCT(('Form responses 1'!$E$2:$E1000 = A2) * ('Form responses 1'!$A$2:$A1000 <= DATE(2025, 5, 31))) + SUMPRODUCT(('Form responses 1'!$F$2:$F1000 = A2) * ('Form responses 1'!$A$2:$A1000 <= DATE(2025, 5, 31))) + SUMPRODUCT(('Form responses 1'!$G$2:$G1000 = A2) * ('Form responses 1'!$A$2:$A1000 <= DATE(2025, 5, 31)))), 2), "-") -> 0.11 | T2: =IFERROR(ROUND(Data!B2/(SUMPRODUCT(('Form responses 1'!$B$2:$B1000 = A2) * ('Form responses 1'!$A$2:$A1000 <= DATE(2025, 6, 30))) + SUMPRODUCT(('Form responses 1'!$C$2:$C1000 = A2) * ('Form responses 1'!$A$2:$A1000 <= DATE(2025, 6, 30))) + SUMPRODUCT(('Form responses 1'!$D$2:$D1000 = A2) * ('Form responses 1'!$A$2:$A1000 <= DATE(2025, 6, 30))) + SUMPRODUCT(('Form responses 1'!$E$2:$E1000 = A2) * ('Form responses 1'!$A$2:$A1000 <= DATE(2025, 6, 30))) + SUMPRODUCT(('Form responses 1'!$F$2:$F1000 = A2) * ('Form responses 1'!$A$2:$A1000 <= DATE(2025, 6, 30))) + SUMPRODUCT(('Form responses 1'!$G$2:$G1000 = A2) * ('Form responses 1'!$A$2:$A1000 <= DATE(2025, 6, 30)))), 2), "-") -> 0.11 | U2: =IFERROR(ROUND(Data!B2/(SUMPRODUCT(('Form responses 1'!$B$2:$B1000 = A2) * ('Form responses 1'!$A$2:$A1000 <= DATE(2025, 7, 31))) + SUMPRODUCT(('Form responses 1'!$C$2:$C1000 = A2) * ('Form responses 1'!$A$2:$A1000 <= DATE(2025, 7, 31))) + SUMPRODUCT(('Form responses 1'!$D$2:$D1000 = A2) * ('Form responses 1'!$A$2:$A1000 <= DATE(2025, 7, 31))) + SUMPRODUCT(('Form responses 1'!$E$2:$E1000 = A2) * ('Form responses 1'!$A$2:$A1000 <= DATE(2025, 7, 31))) + SUMPRODUCT(('Form responses 1'!$F$2:$F1000 = A2) * ('Form responses 1'!$A$2:$A1000 <= DATE(2025, 7, 31))) + SUMPRODUCT(('Form responses 1'!$G$2:$G1000 = A2) * ('Form responses 1'!$A$2:$A1000 <= DATE(2025, 7, 31)))), 2), "-") -> 0.11 | V2: =IFERROR(ROUND(Data!B2/(SUMPRODUCT(('Form responses 1'!$B$2:$B1000 = A2) * ('Form responses 1'!$A$2:$A1000 <= DATE(2025, 8, 31))) + SUMPRODUCT(('Form responses 1'!$C$2:$C1000 = A2) * ('Form responses 1'!$A$2:$A1000 <= DATE(2025, 8, 31))) + SUMPRODUCT(('Form responses 1'!$D$2:$D1000 = A2) * ('Form responses 1'!$A$2:$A1000 <= DATE(2025, 8, 31))) + SUMPRODUCT(('Form responses 1'!$E$2:$E1000 = A2) * ('Form responses 1'!$A$2:$A1000 <= DATE(2025, 8, 31))) + SUMPRODUCT(('Form responses 1'!$F$2:$F1000 = A2) * ('Form responses 1'!$A$2:$A1000 <= DATE(2025, 8, 31))) + SUMPRODUCT(('Form responses 1'!$G$2:$G1000 = A2) * ('Form responses 1'!$A$2:$A1000 <= DATE(2025, 8, 31)))), 2), "-") -> 0.11 | W2: =IFERROR(ROUND(Data!B2/(SUMPRODUCT(('Form responses 1'!$B$2:$B1000 = A2) * ('Form responses 1'!$A$2:$A1000 <= DATE(2025, 9, 30))) + SUMPRODUCT(('Form responses 1'!$C$2:$C1000 = A2) * ('Form responses 1'!$A$2:$A1000 <= DATE(2025, 9, 30))) + SUMPRODUCT(('Form responses 1'!$D$2:$D1000 = A2) * ('Form responses 1'!$A$2:$A1000 <= DATE(2025, 9, 30))) + SUMPRODUCT(('Form responses 1'!$E$2:$E1000 = A2) * ('Form responses 1'!$A$2:$A1000 <= DATE(2025, 9, 30))) + SUMPRODUCT(('Form responses 1'!$F$2:$F1000 = A2) * ('Form responses 1'!$A$2:$A1000 <= DATE(2025, 9, 30))) + SUMPRODUCT(('Form responses 1'!$G$2:$G1000 = A2) * ('Form responses 1'!$A$2:$A1000 <= DATE(2025, 9, 30)))), 2), "-") -> 0.11 | X2: =IFERROR(ROUND(Data!B2/(SUMPRODUCT(('Form responses 1'!$B$2:$B1000 = A2) * ('Form responses 1'!$A$2:$A1000 <= DATE(2025, 10, 31))) + SUMPRODUCT(('Form responses 1'!$C$2:$C1000 = A2) * ('Form responses 1'!$A$2:$A1000 <= DATE(2025, 10, 31))) + SUMPRODUCT(('Form responses 1'!$D$2:$D1000 = A2) * ('Form responses 1'!$A$2:$A1000 <= DATE(2025, 10, 31))) + SUMPRODUCT(('Form responses 1'!$E$2:$E1000 = A2) * ('Form responses 1'!$A$2:$A1000 <= DATE(2025, 10, 31))) + SUMPRODUCT(('Form responses 1'!$F$2:$F1000 = A2) * ('Form responses 1'!$A$2:$A1000 <= DATE(2025, 10, 31))) + SUMPRODUCT(('Form responses 1'!$G$2:$G1000 = A2) * ('Form responses 1'!$A$2:$A1000 <= DATE(2025, 10, 31)))), 2), "-") -> 0.1 | Y2: =IFERROR(ROUND(Data!B2/(SUMPRODUCT(('Form responses 1'!$B$2:$B1000 = A2) * ('Form responses 1'!$A$2:$A1000 <= DATE(2025, 11, 30))) + SUMPRODUCT(('Form responses 1'!$C$2:$C1000 = A2) * ('Form responses 1'!$A$2:$A1000 <= DATE(2025, 11, 30))) + SUMPRODUCT(('Form responses 1'!$D$2:$D1000 = A2) * ('Form responses 1'!$A$2:$A1000 <= DATE(2025, 11, 30))) + SUMPRODUCT(('Form responses 1'!$E$2:$E1000 = A2) * ('Form responses 1'!$A$2:$A1000 <= DATE(2025, 11, 30))) + SUMPRODUCT(('Form responses 1'!$F$2:$F1000 = A2) * ('Form responses 1'!$A$2:$A1000 <= DATE(2025, 11, 30))) + SUMPRODUCT(('Form responses 1'!$G$2:$G1000 = A2) * ('Form responses 1'!$A$2:$A1000 <= DATE(2025, 11, 30)))), 2), "-") -> 0.1 | Z2: =IFERROR(ROUND(Data!B2/(SUMPRODUCT(('Form responses 1'!$B$2:$B1000 = A2) * ('Form responses 1'!$A$2:$A1000 <= DATE(2025, 12, 31))) + SUMPRODUCT(('Form responses 1'!$C$2:$C1000 = A2) * ('Form responses 1'!$A$2:$A1000 <= DATE(2025, 12, 31))) + SUMPRODUCT(('Form responses 1'!$D$2:$D1000 = A2) * ('Form responses 1'!$A$2:$A1000 <= DATE(2025, 12, 31))) + SUMPRODUCT(('Form responses 1'!$E$2:$E1000 = A2) * ('Form responses 1'!$A$2:$A1000 <= DATE(2025, 12, 31))) + SUMPRODUCT(('Form responses 1'!$F$2:$F1000 = A2) * ('Form responses 1'!$A$2:$A1000 <= DATE(2025, 12, 31))) + SUMPRODUCT(('Form responses 1'!$G$2:$G1000 = A2) * ('Form responses 1'!$A$2:$A1000 <= DATE(2025, 12, 31)))), 2), "-") -> 0.1 | AA2: =IFERROR(ROUND(Data!$B2/( SUMPRODUCT(('Form responses 1'!$B$2:$B1000=$A2)*('Form responses 1'!$A$2:$A1000<=EOMONTH(DATEVALUE("1 "&AA$1),0)))+ SUMPRODUCT(('Form responses 1'!$C$2:$C1000=$A2)*('Form responses 1'!$A$2:$A1000<=EOMONTH(DATEVALUE("1 "&AA$1),0)))+ SUMPRODUCT(('Form responses 1'!$D$2:$D1000=$A2)*('Form responses 1'!$A$2:$A1000<=EOMONTH(DATEVALUE("1 "&AA$1),0)))+ SUMPRODUCT(('Form responses 1'!$E$2:$E1000=$A2)*('Form responses 1'!$A$2:$A1000<=EOMONTH(DATEVALUE("1 "&AA$1),0)))+ SUMPRODUCT(('Form responses 1'!$F$2:$F1000=$A2)*('Form responses 1'!$A$2:$A1000<=EOMONTH(DATEVALUE("1 "&AA$1),0)))+ SUMPRODUCT(('Form responses 1'!$G$2:$G1000=$A2)*('Form responses 1'!$A$2:$A1000<=EOMONTH(DATEVALUE("1 "&AA$1),0))) ),2),"-") -> 0.1 | AB2: =IFERROR(ROUND(Data!$B2/( SUMPRODUCT(('Form responses 1'!$B$2:$B1000=$A2)*('Form responses 1'!$A$2:$A1000<=EOMONTH(DATEVALUE("1 "&AB$1),0)))+ SUMPRODUCT(('Form responses 1'!$C$2:$C1000=$A2)*('Form responses 1'!$A$2:$A1000<=EOMONTH(DATEVALUE("1 "&AB$1),0)))+ SUMPRODUCT(('Form responses 1'!$D$2:$D1000=$A2)*('Form responses 1'!$A$2:$A1000<=EOMONTH(DATEVALUE("1 "&AB$1),0)))+ SUMPRODUCT(('Form responses 1'!$E$2:$E1000=$A2)*('Form responses 1'!$A$2:$A1000<=EOMONTH(DATEVALUE("1 "&AB$1),0)))+ SUMPRODUCT(('Form responses 1'!$F$2:$F1000=$A2)*('Form responses 1'!$A$2:$A1000<=EOMONTH(DATEVALUE("1 "&AB$1),0)))+ SUMPRODUCT(('Form responses 1'!$G$2:$G1000=$A2)*('Form responses 1'!$A$2:$A1000<=EOMONTH(DATEVALUE("1 "&AB$1),0))) ),2),"-") -> 0.1 | AC2: =IFERROR(ROUND(Data!$B2/( SUMPRODUCT(('Form responses 1'!$B$2:$B1000=$A2)*('Form responses 1'!$A$2:$A1000<=EOMONTH(DATEVALUE("1 "&AC$1),0)))+ SUMPRODUCT(('Form responses 1'!$C$2:$C1000=$A2)*('Form responses 1'!$A$2:$A1000<=EOMONTH(DATEVALUE("1 "&AC$1),0)))+ SUMPRODUCT(('Form responses 1'!$D$2:$D1000=$A2)*('Form responses 1'!$A$2:$A1000<=EOMONTH(DATEVALUE("1 "&AC$1),0)))+ SUMPRODUCT(('Form responses 1'!$E$2:$E1000=$A2)*('Form responses 1'!$A$2:$A1000<=EOMONTH(DATEVALUE("1 "&AC$1),0)))+ SUMPRODUCT(('Form responses 1'!$F$2:$F1000=$A2)*('Form responses 1'!$A$2:$A1000<=EOMONTH(DATEVALUE("1 "&AC$1),0)))+ SUMPRODUCT(('Form responses 1'!$G$2:$G1000=$A2)*('Form responses 1'!$A$2:$A1000<=EOMONTH(DATEVALUE("1 "&AC$1),0))) ),2),"-") -> 0.1 | AD2: =IFERROR(ROUND(Data!$B2/( SUMPRODUCT(('Form responses 1'!$B$2:$B1000=$A2)*('Form responses 1'!$A$2:$A1000<=EOMONTH(DATEVALUE("1 "&AD$1),0)))+ SUMPRODUCT(('Form responses 1'!$C$2:$C1000=$A2)*('Form responses 1'!$A$2:$A1000<=EOMONTH(DATEVALUE("1 "&AD$1),0)))+ SUMPRODUCT(('Form responses 1'!$D$2:$D1000=$A2)*('Form responses 1'!$A$2:$A1000<=EOMONTH(DATEVALUE("1 "&AD$1),0)))+ SUMPRODUCT(('Form responses 1'!$E$2:$E1000=$A2)*('Form responses 1'!$A$2:$A1000<=EOMONTH(DATEVALUE("1 "&AD$1),0)))+ SUMPRODUCT(('Form responses 1'!$F$2:$F1000=$A2)*('Form responses 1'!$A$2:$A1000<=EOMONTH(DATEVALUE("1 "&AD$1),0)))+ SUMPRODUCT(('Form responses 1'!$G$2:$G1000=$A2)*('Form responses 1'!$A$2:$A1000<=EOMONTH(DATEVALUE("1 "&AD$1),0))) ),2),"-") -> - | AE2: =IFERROR(ROUND(Data!$B2/( SUMPRODUCT(('Form responses 1'!$B$2:$B1000=$A2)*('Form responses 1'!$A$2:$A1000<=EOMONTH(DATEVALUE("1 "&AE$1),0)))+ SUMPRODUCT(('Form responses 1'!$C$2:$C1000=$A2)*('Form responses 1'!$A$2:$A1000<=EOMONTH(DATEVALUE("1 "&AE$1),0)))+ SUMPRODUCT(('Form responses 1'!$D$2:$D1000=$A2)*('Form responses 1'!$A$2:$A1000<=EOMONTH(DATEVALUE("1 "&AE$1),0)))+ SUMPRODUCT(('Form responses 1'!$E$2:$E1000=$A2)*('Form responses 1'!$A$2:$A1000<=EOMONTH(DATEVALUE("1 "&AE$1),0)))+ SUMPRODUCT(('Form responses 1'!$F$2:$F1000=$A2)*('Form responses 1'!$A$2:$A1000<=EOMONTH(DATEVALUE("1 "&AE$1),0)))+ SUMPRODUCT(('Form responses 1'!$G$2:$G1000=$A2)*('Form responses 1'!$A$2:$A1000<=EOMONTH(DATEVALUE("1 "&AE$1),0))) ),2),"-") -> - | AF2: =IFERROR(ROUND(Data!$B2/( SUMPRODUCT(('Form responses 1'!$B$2:$B1000=$A2)*('Form responses 1'!$A$2:$A1000<=EOMONTH(DATEVALUE("1 "&AF$1),0)))+ SUMPRODUCT(('Form responses 1'!$C$2:$C1000=$A2)*('Form responses 1'!$A$2:$A1000<=EOMONTH(DATEVALUE("1 "&AF$1),0)))+ SUMPRODUCT(('Form responses 1'!$D$2:$D1000=$A2)*('Form responses 1'!$A$2:$A1000<=EOMONTH(DATEVALUE("1 "&AF$1),0)))+ SUMPRODUCT(('Form responses 1'!$E$2:$E1000=$A2)*('Form responses 1'!$A$2:$A1000<=EOMONTH(DATEVALUE("1 "&AF$1),0)))+ SUMPRODUCT(('Form responses 1'!$F$2:$F1000=$A2)*('Form responses 1'!$A$2:$A1000<=EOMONTH(DATEVALUE("1 "&AF$1),0)))+ SUMPRODUCT(('Form responses 1'!$G$2:$G1000=$A2)*('Form responses 1'!$A$2:$A1000<=EOMONTH(DATEVALUE("1 "&AF$1),0))) ),2),"-") -> - | AG2: =IFERROR(ROUND(Data!$B2/( SUMPRODUCT(('Form responses 1'!$B$2:$B1000=$A2)*('Form responses 1'!$A$2:$A1000<=EOMONTH(DATEVALUE("1 "&AG$1),0)))+ SUMPRODUCT(('Form responses 1'!$C$2:$C1000=$A2)*('Form responses 1'!$A$2:$A1000<=EOMONTH(DATEVALUE("1 "&AG$1),0)))+ SUMPRODUCT(('Form responses 1'!$D$2:$D1000=$A2)*('Form responses 1'!$A$2:$A1000<=EOMONTH(DATEVALUE("1 "&AG$1),0)))+ SUMPRODUCT(('Form responses 1'!$E$2:$E1000=$A2)*('Form responses 1'!$A$2:$A1000<=EOMONTH(DATEVALUE("1 "&AG$1),0)))+ SUMPRODUCT(('Form responses 1'!$F$2:$F1000=$A2)*('Form responses 1'!$A$2:$A1000<=EOMONTH(DATEVALUE("1 "&AG$1),0)))+ SUMPRODUCT(('Form responses 1'!$G$2:$G1000=$A2)*('Form responses 1'!$A$2:$A1000<=EOMONTH(DATEVALUE("1 "&AG$1),0))) ),2),"-") -> - | AH2: =IFERROR(ROUND(Data!$B2/( SUMPRODUCT(('Form responses 1'!$B$2:$B1000=$A2)*('Form responses 1'!$A$2:$A1000<=EOMONTH(DATEVALUE("1 "&AH$1),0)))+ SUMPRODUCT(('Form responses 1'!$C$2:$C1000=$A2)*('Form responses 1'!$A$2:$A1000<=EOMONTH(DATEVALUE("1 "&AH$1),0)))+ SUMPRODUCT(('Form responses 1'!$D$2:$D1000=$A2)*('Form responses 1'!$A$2:$A1000<=EOMONTH(DATEVALUE("1 "&AH$1),0)))+ SUMPRODUCT(('Form responses 1'!$E$2:$E1000=$A2)*('Form responses 1'!$A$2:$A1000<=EOMONTH(DATEVALUE("1 "&AH$1),0)))+ SUMPRODUCT(('Form responses 1'!$F$2:$F1000=$A2)*('Form responses 1'!$A$2:$A1000<=EOMONTH(DATEVALUE("1 "&AH$1),0)))+ SUMPRODUCT(('Form responses 1'!$G$2:$G1000=$A2)*('Form responses 1'!$A$2:$A1000<=EOMONTH(DATEVALUE("1 "&AH$1),0))) ),2),"-") -> - | ... AL2: =IFERROR(ROUND(Data!$B2/( SUMPRODUCT(('Form responses 1'!$B$2:$B1000=$A2)*('Form responses 1'!$A$2:$A1000<=EOMONTH(DATEVALUE("1 "&AL$1),0)))+ SUMPRODUCT(('Form responses 1'!$C$2:$C1000=$A2)*('Form responses 1'!$A$2:$A1000<=EOMONTH(DATEVALUE("1 "&AL$1),0)))+ SUMPRODUCT(('Form responses 1'!$D$2:$D1000=$A2)*('Form responses 1'!$A$2:$A1000<=EOMONTH(DATEVALUE("1 "&AL$1),0)))+ SUMPRODUCT(('Form responses 1'!$E$2:$E1000=$A2)*('Form responses 1'!$A$2:$A1000<=EOMONTH(DATEVALUE("1 "&AL$1),0)))+ SUMPRODUCT(('Form responses 1'!$F$2:$F1000=$A2)*('Form responses 1'!$A$2:$A1000<=EOMONTH(DATEVALUE("1 "&AL$1),0)))+ SUMPRODUCT(('Form responses 1'!$G$2:$G1000=$A2)*('Form responses 1'!$A$2:$A1000<=EOMONTH(DATEVALUE("1 "&AL$1),0))) ),2),"-") -> -
